<?xml version='1.0' encoding='UTF-8'?>
<mujoco>
  <worldbody>
    <body pos="0.0 0.0 0.0" name="body_1_base">
      <inertial mass="0.0" pos="0.0 0.0 0.0" quat="0.0 0.0 0.0 0.0" diaginertia="0.0 0.0 0.0"/>
      <geom size="0.0 0.0" pos="0.0 0.0 0.0" quat="0.0 0.0 0.0 0.0"/>
      <body pos="0.0 0.0 0.0" name="body_2_FL_hip">
        <inertial mass="0.0" pos="0.0 0.0 0.0" quat="0.0 0.0 0.0 0.0" diaginertia="0.0 0.0 0.0"/>
        <geom size="0.0 0.0" pos="0.0 0.0 0.0" quat="0.0 0.0 0.0 0.0"/>
        <joint name="joint_1_FL_hip_joint" range="0.0 0.0" stiffness="0.0" axis="0.0 0.0 0.0" pos="0.0 0.0 0.0"/>
        <body pos="0.0 0.0 0.0" name="body_3_FL_thigh">
          <inertial mass="0.0" pos="0.0 0.0 0.0" quat="0.0 0.0 0.0 0.0" diaginertia="0.0 0.0 0.0"/>
          <geom size="0.0 0.0" pos="0.0 0.0 0.0" quat="0.0 0.0 0.0 0.0"/>
          <joint name="joint_2_FL_thigh_joint" range="0.0 0.0" stiffness="0.0" axis="0.0 0.0 0.0" pos="0.0 0.0 0.0"/>
          <body pos="0.0 0.0 0.0" name="body_4_FL_calf">
            <inertial mass="0.0" pos="0.0 0.0 0.0" quat="0.0 0.0 0.0 0.0" diaginertia="0.0 0.0 0.0"/>
            <geom size="0.0 0.0" pos="0.0 0.0 0.0" quat="0.0 0.0 0.0 0.0"/>
            <joint name="joint_3_FL_calf_joint" range="0.0 0.0" stiffness="0.0" axis="0.0 0.0 0.0" pos="0.0 0.0 0.0"/>
          </body>
        </body>
      </body>
      <body pos="0.0 0.0 0.0" name="body_5_FR_hip">
        <inertial mass="0.0" pos="0.0 0.0 0.0" quat="0.0 0.0 0.0 0.0" diaginertia="0.0 0.0 0.0"/>
        <geom size="0.0 0.0" pos="0.0 0.0 0.0" quat="0.0 0.0 0.0 0.0"/>
        <joint name="joint_4_FR_hip_joint" range="0.0 0.0" stiffness="0.0" axis="0.0 0.0 0.0" pos="0.0 0.0 0.0"/>
        <body pos="0.0 0.0 0.0" name="body_6_FR_thigh">
          <inertial mass="0.0" pos="0.0 0.0 0.0" quat="0.0 0.0 0.0 0.0" diaginertia="0.0 0.0 0.0"/>
          <geom size="0.0 0.0" pos="0.0 0.0 0.0" quat="0.0 0.0 0.0 0.0"/>
          <joint name="joint_5_FR_thigh_joint" range="0.0 0.0" stiffness="0.0" axis="0.0 0.0 0.0" pos="0.0 0.0 0.0"/>
          <body pos="0.0 0.0 0.0" name="body_7_FR_calf">
            <inertial mass="0.0" pos="0.0 0.0 0.0" quat="0.0 0.0 0.0 0.0" diaginertia="0.0 0.0 0.0"/>
            <geom size="0.0 0.0" pos="0.0 0.0 0.0" quat="0.0 0.0 0.0 0.0"/>
            <joint name="joint_6_FR_calf_joint" range="0.0 0.0" stiffness="0.0" axis="0.0 0.0 0.0" pos="0.0 0.0 0.0"/>
          </body>
        </body>
      </body>
      <body pos="0.0 0.0 0.0" name="body_8_RL_hip">
        <inertial mass="0.0" pos="0.0 0.0 0.0" quat="0.0 0.0 0.0 0.0" diaginertia="0.0 0.0 0.0"/>
        <geom size="0.0 0.0" pos="0.0 0.0 0.0" quat="0.0 0.0 0.0 0.0"/>
        <joint name="joint_7_RL_hip_joint" range="0.0 0.0" stiffness="0.0" axis="0.0 0.0 0.0" pos="0.0 0.0 0.0"/>
        <body pos="0.0 0.0 0.0" name="body_9_RL_thigh">
          <inertial mass="0.0" pos="0.0 0.0 0.0" quat="0.0 0.0 0.0 0.0" diaginertia="0.0 0.0 0.0"/>
          <geom size="0.0 0.0" pos="0.0 0.0 0.0" quat="0.0 0.0 0.0 0.0"/>
          <joint name="joint_8_RL_thigh_joint" range="0.0 0.0" stiffness="0.0" axis="0.0 0.0 0.0" pos="0.0 0.0 0.0"/>
          <body pos="0.0 0.0 0.0" name="body_10_RL_calf">
            <inertial mass="0.0" pos="0.0 0.0 0.0" quat="0.0 0.0 0.0 0.0" diaginertia="0.0 0.0 0.0"/>
            <geom size="0.0 0.0" pos="0.0 0.0 0.0" quat="0.0 0.0 0.0 0.0"/>
            <joint name="joint_9_RL_calf_joint" range="0.0 0.0" stiffness="0.0" axis="0.0 0.0 0.0" pos="0.0 0.0 0.0"/>
          </body>
        </body>
      </body>
      <body pos="0.0 0.0 0.0" name="body_11_RR_hip">
        <inertial mass="0.0" pos="0.0 0.0 0.0" quat="0.0 0.0 0.0 0.0" diaginertia="0.0 0.0 0.0"/>
        <geom size="0.0 0.0" pos="0.0 0.0 0.0" quat="0.0 0.0 0.0 0.0"/>
        <joint name="joint_10_RR_hip_joint" range="0.0 0.0" stiffness="0.0" axis="0.0 0.0 0.0" pos="0.0 0.0 0.0"/>
        <body pos="0.0 0.0 0.0" name="body_12_RR_thigh">
          <inertial mass="0.0" pos="0.0 0.0 0.0" quat="0.0 0.0 0.0 0.0" diaginertia="0.0 0.0 0.0"/>
          <geom size="0.0 0.0" pos="0.0 0.0 0.0" quat="0.0 0.0 0.0 0.0"/>
          <joint name="joint_11_RR_thigh_joint" range="0.0 0.0" stiffness="0.0" axis="0.0 0.0 0.0" pos="0.0 0.0 0.0"/>
          <body pos="0.0 0.0 0.0" name="body_13_RR_calf">
            <inertial mass="0.0" pos="0.0 0.0 0.0" quat="0.0 0.0 0.0 0.0" diaginertia="0.0 0.0 0.0"/>
            <geom size="0.0 0.0" pos="0.0 0.0 0.0" quat="0.0 0.0 0.0 0.0"/>
            <joint name="joint_12_RR_calf_joint" range="0.0 0.0" stiffness="0.0" axis="0.0 0.0 0.0" pos="0.0 0.0 0.0"/>
          </body>
        </body>
      </body>
    </body>
  </worldbody>
</mujoco>
