<mujoco model="T‑Rex">
  <compiler angle="degree" coordinate="local" inertiafromgeom="true"/>
  <default>
    <joint limited="true" damping="1" armature="0.1"/>
    <geom conaffinity="1" condim="3" friction="1 0.5 0.5" margin="0.01" solref="0.02 1"/>
  </default>
  <worldbody>
    <light directional="true" diffuse="0.8 0.8 0.8" pos="0 0 5" dir="0 0 -1"/>
    <geom type="plane" size="50 50 0.1" rgba="0.2 0.3 0.4 1"/>
    <body name="torso" pos="0 0 1.5">
      <camera name="track" mode="track" pos="0 -5 2" xyaxes="1 0 0 0 1 0"/>
      <joint type="free"/>
      <geom name="torso_geom" type="capsule" fromto="0 0 0 0 0 -0.7" size="0.3"/>
      
      <!-- Left Leg -->
      <body name="left_thigh" pos="0.2 0 -0.7">
        <joint name="left_hip" type="hinge" axis="0 1 0" range="-90 45"/>
        <geom name="left_thigh_geom" type="capsule" fromto="0 0 0 0 0 -0.5" size="0.15"/>
        <body name="left_shin" pos="0 0 -0.5">
          <joint name="left_knee" type="hinge" axis="0 1 0" range="-160 0"/>
          <geom name="left_shin_geom" type="capsule" fromto="0 0 0 0 0 -0.6" size="0.1"/>
          <body name="left_foot" pos="0 0 -0.6">
            <joint name="left_ankle" type="hinge" axis="0 1 0" range="-45 45"/>
            <geom name="left_foot_geom" type="capsule" fromto="0 0 0 0.2 0 -0.1" size="0.08"/>
            <body name="left_toe" pos="0.2 0 -0.1">
              <joint name="left_toe_joint" type="hinge" axis="0 1 0" range="-20 45"/>
              <geom name="left_toe_geom" type="capsule" fromto="0 0 0 0.2 0 0" size="0.06"/>
            </body>
          </body>
        </body>
      </body>
      
      <!-- Right Leg -->
      <body name="right_thigh" pos="-0.2 0 -0.7">
        <joint name="right_hip" type="hinge" axis="0 1 0" range="-90 45"/>
        <geom name="right_thigh_geom" type="capsule" fromto="0 0 0 0 0 -0.5" size="0.15"/>
        <body name="right_shin" pos="0 0 -0.5">
          <joint name="right_knee" type="hinge" axis="0 1 0" range="-160 0"/>
          <geom name="right_shin_geom" type="capsule" fromto="0 0 0 0 0 -0.6" size="0.1"/>
          <body name="right_foot" pos="0 0 -0.6">
            <joint name="right_ankle" type="hinge" axis="0 1 0" range="-45 45"/>
            <geom name="right_foot_geom" type="capsule" fromto="0 0 0 0.2 0 -0.1" size="0.08"/>
            <body name="right_toe" pos="0.2 0 -0.1">
              <joint name="right_toe_joint" type="hinge" axis="0 1 0" range="-20 45"/>
              <geom name="right_toe_geom" type="capsule" fromto="0 0 0 0.2 0 0" size="0.06"/>
            </body>
          </body>
        </body>
      </body>
      
      
    </body>
  </worldbody>
  
  <actuator>
    <motor name="left_hip" joint="left_hip" gear="120"/>
    <motor name="left_knee" joint="left_knee" gear="120"/>
    <motor name="left_ankle" joint="left_ankle" gear="120"/>
    <motor name="left_toe" joint="left_toe_joint" gear="120"/>
    <motor name="right_hip" joint="right_hip" gear="120"/>
    <motor name="right_knee" joint="right_knee" gear="120"/>
    <motor name="right_ankle" joint="right_ankle" gear="120"/>
    <motor name="right_toe" joint="right_toe_joint" gear="120"/>
  </actuator>
</mujoco>