<?xml version="1.0" ?>
<mujoco model="generated_robot">
  <compiler angle="radian" autolimits="true"/>
  <option cone="elliptic" impratio="100"/>
  <default>
    <default class="robot">
      <geom friction="0.6" margin="0.001"/>
      <joint damping="2" armature="0.01"/>
    </default>
  </default>
  <worldbody>
    <body name="body_0" pos="0.0001559099182486534 -2.3074069758877158e-05 0.4458831548690796" quat="1.0000097751617432 -0.0001415051519870758 -8.110888302326202e-05 1.9720755517482758e-05">
      <inertial mass="5.231388092041016" diaginertia="0.07207655161619186 0.0632186233997345 0.016897588968276978" pos="0.02246175892651081 0.002006569877266884 -0.00015807151794433594" quat="-0.004950523376464844 0.7062672972679138 -0.00026706233620643616 0.7086466550827026"/>
      <geom name="geom_body_0" type="box" size="0.12551146745681763 0.04006735980510712 0.057250600308179855" pos="0.0001246002793777734 -6.838497938588262e-06 9.211711585521698e-05" quat="1.0018309354782104 -8.264929056167603e-05 1.4204531908035278e-05 -0.00035299058072268963"/>
      <joint name="joint_1_body_0" type="hinge" axis="0.000764116644859314 0.0007713437080383301 1.0017271041870117" range="0.0018395185470581055 -0.005660414695739746" pos="8.658831939101219e-05 0.0015266609843820333 -0.0009988155215978622" stiffness="0.0072043659165501595"/>
      <joint name="joint_2_body_0" type="hinge" axis="1.0032436847686768 -0.0008791089057922363 0.0009414255619049072" range="0 0.86902916431427" pos="0.0011647394858300686 -0.002144098514690995 0.004236141219735146" stiffness="0.00543475616723299"/>
      <body name="body_3" pos="0.18822450935840607 -0.04666043445467949 0.0008230721578001976" quat="0.9996806979179382 0.00041278451681137085 0.0002489890903234482 1.9570812582969666e-05">
        <inertial mass="0.6856133937835693" diaginertia="0.0007475847378373146 0.0006213430315256119 0.0004306142218410969" pos="-0.004905139561742544 0.007485401816666126 0.00038465484976768494" quat="0.5059846639633179 0.5159139037132263 0.49476996064186096 0.48435842990875244"/>
        <geom name="geom_body_3" type="box" size="0.045929498970508575 0.019716305658221245 6.724381819367409e-05" pos="9.386910824105144e-05 -0.044620614498853683 2.8088688850402832e-05" quat="0.7075098752975464 0.7080214619636536 -0.0007904134690761566 -0.0002954199444502592"/>
        <joint name="joint_2_body_3" type="ball" axis="1.0032436847686768 -0.0008791089057922363 0.0009414255619049072" range="0 0.86902916431427" pos="0.0011647394858300686 -0.002144098514690995 0.004236141219735146" stiffness="0.00543475616723299"/>
        <joint name="joint_4_body_3" type="ball" axis="0.0004407614469528198 0.9987324476242065 -0.0003224611282348633" range="0 4.502537250518799" pos="0.0016024238429963589 0.0020660085137933493 0.0034484360367059708" stiffness="0.008321848697960377"/>
        <body name="body_5" pos="0.00023937819059938192 -0.08005650341510773 0.00034152623265981674" quat="1.0001522302627563 -0.0003097411245107651 0.0002756323665380478 6.017275154590607e-05">
          <inertial mass="1.0211026668548584" diaginertia="0.004781339317560196 0.004926311317831278 0.0006828473415225744" pos="-0.0030611567199230194 0.019222833216190338 -0.0296938419342041" quat="0.649500846862793 -0.026713043451309204 0.07670868933200836 0.7574440240859985"/>
          <geom name="geom_body_5" type="box" size="0.015474516898393631 0.07941785454750061 0.0001544523984193802" pos="-0.019892051815986633 1.7923739505931735e-05 -0.07980010658502579" quat="1.0008729696273804 0.0004203692078590393 0.004848208278417587 -5.0697941333055496e-05"/>
          <joint name="joint_4_body_5" type="ball" axis="0.0004407614469528198 0.9987324476242065 -0.0003224611282348633" range="-0.6880797147750854 4.502537250518799" pos="0.0016024238429963589 0.0020660085137933493 0.0034484360367059708" stiffness="0.008321848697960377"/>
          <joint name="joint_6_body_5" type="free" axis="-0.0007094591856002808 0.9972268342971802 0.00032025575637817383" range="-2.822963237762451 -0.8801940679550171" pos="0.0008466816507279873 0.0029061955865472555 -0.0007927771657705307"/>
          <body name="body_7" pos="0.00018269370775669813 -0.00015311286551877856 -0.21187418699264526" quat="0.9994385242462158 -3.306940197944641e-05 4.275701940059662e-05 0.0002353861927986145">
            <inertial mass="0.20291292667388916" diaginertia="0.0017205923795700073 0.001253519207239151 2.9604649171233177e-05" pos="0.004125921055674553 0.001050538499839604 -0.14649400115013123" quat="0.6930393576622009 0.002970069646835327 0.0029065385460853577 0.7221724987030029"/>
            <geom name="geom_body_7" type="cylinder" size="0.010025976225733757 0.06574717164039612" pos="0.010061888955533504 9.575975127518177e-06 -0.06522606313228607" quat="0.9983668923377991 0.0022449493408203125 -0.07306790351867676 -0.00040663802064955235"/>
            <joint name="joint_6_body_7" type="free" axis="-0.0007094591856002808 0.9972268342971802 0.00032025575637817383" range="-2.822963237762451 -0.8801940679550171" pos="0.0008466816507279873 0.0029061955865472555 -0.0007927771657705307"/>
          </body>
        </body>
      </body>
      <joint name="joint_8_body_0" type="hinge" axis="1.0013433694839478 -0.0006708502769470215 0.0011327266693115234" range="0 0.8634499907493591" pos="-0.00013460451737046242 0.00021923310123384 -0.004621079191565514" stiffness="0.004417878575623035"/>
      <body name="body_9" pos="0.18831942975521088 0.04649312049150467 0.00016293954104185104" quat="0.9998779892921448 -1.9609928131103516e-05 0.0001656748354434967 -7.758941501379013e-05">
        <inertial mass="0.6900022625923157" diaginertia="0.000690150074660778 0.0004754820838570595 0.0004710142966359854" pos="-0.004809767473489046 -0.0076555595733225346 0.0002464763820171356" quat="0.4829453229904175 0.4951517581939697 0.513404905796051 0.5089518427848816"/>
        <geom name="geom_body_9" type="box" size="0.04603803530335426 0.01974235475063324 0.0001262882724404335" pos="4.497682675719261e-05 0.04473879188299179 -0.0002659466117620468" quat="0.7096114158630371 0.7072283625602722 0.0002764556556940079 -0.0006416684482246637"/>
        <joint name="joint_8_body_9" type="ball" axis="1.0013433694839478 -0.0006708502769470215 0.0011327266693115234" range="-0.861674964427948 0.8634499907493591" pos="-0.00013460451737046242 0.00021923310123384 -0.004621079191565514" stiffness="0.004417878575623035"/>
        <joint name="joint_10_body_9" type="ball" axis="-0.0013798773288726807 0.9978463649749756 0.0007652342319488525" range="-0.6886460781097412 4.505835056304932" pos="-0.0009174072183668613 -0.0025598781649023294 0.0005572233349084854" stiffness="0.0031467946246266365"/>
        <body name="body_11" pos="9.616720490157604e-06 0.07978498190641403 0.000287029892206192" quat="0.9998443722724915 -0.0006639156490564346 -7.592141628265381e-06 0.0003182338550686836">
          <inertial mass="1.021998643875122" diaginertia="0.004735410213470459 0.004679172765463591 0.0007465369999408722" pos="-0.0030621495097875595 -0.019349927082657814 -0.029802361503243446" quat="0.7505565881729126 0.07823747396469116 -0.027793537825345993 0.6557844281196594"/>
          <geom name="geom_body_11" type="box" size="0.015433249995112419 0.07963097840547562 0.00012821750715374947" pos="-0.019839996472001076 4.451075801625848e-05 -0.07999138534069061" quat="1.0019139051437378 -0.0006290525197982788 0.00475655309855938 7.462059147655964e-05"/>
          <joint name="joint_10_body_11" type="ball" axis="-0.0013798773288726807 0.9978463649749756 0.0007652342319488525" range="-0.6886460781097412 4.505835056304932" pos="-0.0009174072183668613 -0.0025598781649023294 0.0005572233349084854" stiffness="0.0031467946246266365"/>
          <joint name="joint_12_body_11" type="free" axis="-0.000505983829498291 0.9980078935623169 -0.0005637705326080322" range="-2.8258941173553467 -0.8815616369247437" pos="-0.0013963007368147373 -0.003459893399849534 -0.0013032760471105576" stiffness="0.0026979120448231697"/>
          <body name="body_13" pos="0.00028330518398433924 0.00019704242004081607 -0.21119558811187744" quat="0.9995828866958618 -0.0002986881881952286 -0.0001836717128753662 0.0002786600962281227">
            <inertial mass="0.19835209846496582" diaginertia="0.0016031637787818909 0.0012956392019987106 9.740283712744713e-05" pos="0.004155006259679794 0.000994727946817875 -0.14636842906475067" quat="0.6933172941207886 0.002697885036468506 0.0029913149774074554 0.7208156585693359"/>
            <geom name="geom_body_13" type="box" size="0.01007653959095478 0.06570223718881607 6.973836570978165e-05" pos="0.010019268840551376 1.1806754628196359e-05 -0.06482456624507904" quat="0.9999570846557617 0.00031529366970062256 -0.0734444186091423 -0.0003394193481653929"/>
            <joint name="joint_12_body_13" type="free" axis="-0.000505983829498291 0.9980078935623169 -0.0005637705326080322" range="-2.8258941173553467 -0.8815616369247437" pos="-0.0013963007368147373 -0.003459893399849534 -0.0013032760471105576" stiffness="0.0026979120448231697"/>
          </body>
        </body>
      </body>
      <joint name="joint_14_body_0" type="hinge" axis="1.0021857023239136 -0.0034814774990081787 0.0015559196472167969" range="0 0.8651149868965149" pos="0.005525571759790182 -0.0046056583523750305 -0.004154851660132408" stiffness="0.006169465370476246"/>
      <body name="body_15" pos="-0.1881123036146164 -0.04679258167743683 0.0005626911297440529" quat="0.9998038411140442 0.00018290244042873383 -0.00011578947305679321 6.900355219841003e-05">
        <inertial mass="0.6879438161849976" diaginertia="0.0008071772754192352 0.00030413269996643066 0.00045510008931159973" pos="0.0050132726319134235 0.007556266151368618 0.000651434063911438" quat="0.49582207202911377 0.48264646530151367 0.5063480734825134 0.5155770778656006"/>
        <geom name="geom_body_15" type="box" size="0.04605630785226822 0.01986313797533512 0.00011504581198096275" pos="5.133368540555239e-05 -0.04548663645982742 0.0001941286027431488" quat="0.7093026638031006 0.7079410552978516 0.00015624985098838806 -0.0005877704825252295"/>
        <joint name="joint_14_body_15" type="ball" axis="1.0021857023239136 -0.0034814774990081787 0.0015559196472167969" range="-0.8675199747085571 0.8651149868965149" pos="0.005525571759790182 -0.0046056583523750305 -0.004154851660132408" stiffness="0.006169465370476246"/>
        <joint name="joint_16_body_15" type="ball" axis="0.0014895647764205933 0.9998655319213867 -0.0002970695495605469" range="-0.6853617429733276 4.507421970367432" pos="-0.0007888623513281345 0.00041436380706727505 0.0013195816427469254" stiffness="0.005609181709587574"/>
        <body name="body_17" pos="0.00012589828111231327 -0.08038506656885147 0.0009133266285061836" quat="1.0002747774124146 -0.00017413124442100525 -5.6352466344833374e-05 0.00023828446865081787">
          <inertial mass="1.027660846710205" diaginertia="0.004795963875949383 0.004927041474729776 0.0007171835750341415" pos="-0.00307552982121706 0.01954290270805359 -0.029782844707369804" quat="0.6501957178115845 -0.026561081409454346 0.07676324248313904 0.755512535572052"/>
          <geom name="geom_body_17" type="box" size="0.0154616953805089 0.07961426675319672 0.00014763465151190758" pos="-0.019974244758486748 7.227645255625248e-05 -0.07973416149616241" quat="1.0029040575027466 0.0009076744318008423 0.0038947314023971558 -0.00014570681378245354"/>
          <joint name="joint_16_body_17" type="ball" axis="0.0014895647764205933 0.9998655319213867 -0.0002970695495605469" range="-0.6853617429733276 4.507421970367432" pos="-0.0007888623513281345 0.00041436380706727505 0.0013195816427469254" stiffness="0.005609181709587574"/>
          <joint name="joint_18_body_17" type="free" axis="-0.0010257363319396973 0.9983783960342407 0.0008028149604797363" range="-2.821488380432129 -0.8801044225692749" pos="-0.0018534981645643711 -0.0036418067757040262 0.0014244485646486282" stiffness="0.0015435488894581795"/>
          <body name="body_19" pos="0.00019110122229903936 0.0001215506053995341 -0.2111663669347763" quat="0.9993992447853088 -5.1682814955711365e-05 1.0591000318527222e-05 0.00013903342187404633">
            <inertial mass="0.20793545246124268" diaginertia="0.001536472700536251 0.0014491090551018715 7.503270171582699e-05" pos="0.004143183585256338 0.001064481446519494 -0.14618080854415894" quat="0.6931110620498657 0.0033133327960968018 0.0022668875753879547 0.7217390537261963"/>
            <geom name="geom_body_19" type="cylinder" size="0.010056911036372185 0.06571169942617416" pos="0.009975623339414597 7.30063475202769e-05 -0.06510162353515625" quat="0.997787594795227 0.0013688430190086365 -0.07293413579463959 -0.00047225342132151127"/>
            <joint name="joint_18_body_19" type="free" axis="-0.0010257363319396973 0.9983783960342407 0.0008028149604797363" range="-2.821488380432129 -0.8801044225692749" pos="-0.0018534981645643711 -0.0036418067757040262 0.0014244485646486282" stiffness="0.0015435488894581795"/>
          </body>
        </body>
      </body>
      <joint name="joint_20_body_0" type="hinge" axis="1.001636028289795 -0.0014471709728240967 0.0014328360557556152" range="0 0.8618918061256409" pos="0.001024534460157156 -0.0034938978496938944 -0.0072116609662771225" stiffness="0.005431857891380787"/>
      <body name="body_21" pos="-0.1895350068807602 0.04677195101976395 0.0006293589249253273" quat="0.9998080730438232 -0.00012771040201187134 0.0004069022834300995 -0.00012217368930578232">
        <inertial mass="0.693250834941864" diaginertia="0.0009000711143016815 0.0002994425594806671 0.0005044888239353895" pos="0.005076979286968708 -0.007801441941410303 0.0005860067903995514" quat="0.5146531462669373 0.5062254667282104 0.48313963413238525 0.4965269863605499"/>
        <geom name="geom_body_21" type="box" size="0.045875269919633865 0.019821735098958015 0.00016762083396315575" pos="0.0001689755590632558 0.04505588859319687 -0.00011626072227954865" quat="0.70744389295578 0.708260715007782 -0.0006116293370723724 -0.00041417102329432964"/>
        <joint name="joint_20_body_21" type="ball" axis="1.001636028289795 -0.0014471709728240967 0.0014328360557556152" range="-0.8662843704223633 0.8618918061256409" pos="0.001024534460157156 -0.0034938978496938944 -0.0072116609662771225" stiffness="0.005431857891380787"/>
        <joint name="joint_22_body_21" type="ball" axis="-0.00016248226165771484 0.998115062713623 -0.0009303390979766846" range="-0.6833521723747253 4.514345645904541" pos="0.0008558756671845913 0.0017404479440301657 9.571947157382965e-05" stiffness="0.0040293605998158455"/>
        <body name="body_23" pos="0.00013243290595710278 0.08045659959316254 0.0017974944785237312" quat="1.0001543760299683 -0.00021918118000030518 0.00020497292280197144 0.0004849229007959366">
          <inertial mass="1.0264517068862915" diaginertia="0.004843138158321381 0.004883131943643093 0.0007678393740206957" pos="-0.0029949555173516273 -0.019350744783878326 -0.030008036643266678" quat="0.7523447275161743 0.07948502898216248 -0.028274688869714737 0.6533088088035583"/>
          <geom name="geom_body_23" type="box" size="0.015260158106684685 0.07972118258476257 0.00012074178084731102" pos="-0.019936852157115936 6.972262053750455e-05 -0.07998530566692352" quat="1.0028266906738281 -0.00029540807008743286 0.004288177937269211 -7.409858517348766e-05"/>
          <joint name="joint_22_body_23" type="ball" axis="-0.00016248226165771484 0.998115062713623 -0.0009303390979766846" range="-0.6833521723747253 4.514345645904541" pos="0.0008558756671845913 0.0017404479440301657 9.571947157382965e-05" stiffness="0.0040293605998158455"/>
          <joint name="joint_24_body_23" type="free" axis="-2.7164816856384277e-05 1.0013782978057861 0.001072227954864502" range="-2.8247976303100586 -0.8842040300369263" pos="-0.003447862807661295 -0.002624280983582139 0.000902840867638588" stiffness="0.005629238672554493"/>
          <body name="body_25" pos="0.000397959491237998 0.00010335497790947556 -0.21167044341564178" quat="0.9994956851005554 -0.0003835391253232956 2.9046088457107544e-05 0.0005285143852233887">
            <inertial mass="0.202764630317688" diaginertia="0.001629214733839035 0.0013098781928420067 8.994224481284618e-05" pos="0.004049765877425671 0.0010464189108461142 -0.14630091190338135" quat="0.6936948299407959 0.003008812665939331 0.001711677759885788 0.7211692333221436"/>
            <geom name="geom_body_25" type="box" size="0.010303590446710587 0.06575392186641693 1.0785181075334549e-05" pos="0.00999282207340002 6.985332584008574e-05 -0.06529715657234192" quat="0.9999850988388062 7.317215204238892e-05 -0.07193566113710403 -0.00021934416145086288"/>
            <joint name="joint_24_body_25" type="free" axis="-2.7164816856384277e-05 1.0013782978057861 0.001072227954864502" range="-2.8247976303100586 -0.8842040300369263" pos="-0.003447862807661295 -0.002624280983582139 0.000902840867638588" stiffness="0.005629238672554493"/>
          </body>
        </body>
      </body>
    </body>
  </worldbody>
  <actuator>
    <position name="actuator_joint_1_body_0" joint="joint_1_body_0" kp="100"/>
    <position name="actuator_joint_2_body_0" joint="joint_2_body_0" kp="100"/>
    <position name="actuator_joint_4_body_3" joint="joint_4_body_3" kp="100"/>
    <position name="actuator_joint_6_body_5" joint="joint_6_body_5" kp="100"/>
    <position name="actuator_joint_8_body_0" joint="joint_8_body_0" kp="100"/>
    <position name="actuator_joint_10_body_9" joint="joint_10_body_9" kp="100"/>
    <position name="actuator_joint_12_body_11" joint="joint_12_body_11" kp="100"/>
    <position name="actuator_joint_14_body_0" joint="joint_14_body_0" kp="100"/>
    <position name="actuator_joint_16_body_15" joint="joint_16_body_15" kp="100"/>
    <position name="actuator_joint_18_body_17" joint="joint_18_body_17" kp="100"/>
    <position name="actuator_joint_20_body_0" joint="joint_20_body_0" kp="100"/>
    <position name="actuator_joint_22_body_21" joint="joint_22_body_21" kp="100"/>
    <position name="actuator_joint_24_body_23" joint="joint_24_body_23" kp="100"/>
  </actuator>
</mujoco>
